Workbook

Sheet A_實驗計畫
A1: AOI-1 更換 DUC 電磁閥後 — 兩台 DUC 比對實驗計畫
A2: 背景：廠商與 RD 交叉確認 AOI-1 控制 DUC 氣量的電磁閥與 AOI-2 不同（AOI-1 流量較小），已請購同規格電磁閥。本計畫用於換閥後驗證兩台是否一致，作為驗收第22項「機台差異性」之判定依據。
A3: ◤ 目的：確認換閥後兩台 DUC「清潔力」是否一致。
A4: 一、換閥前的證據（為何懷疑 DUC）
B5: 資料 | C5: 觀察 | D5: 代表意義
B6: 實驗5 交叉清潔 | C6: 771A7：AOI-1 先吹飽和 86 → AOI-2 再吹降到 77（再少 10%） 880F0：AOI-2 先吹飽和 176 → AOI-1 再吹 174（只少 1%） | D6: AOI-2 吹得掉 AOI-1 留下的顆粒，反之不行 → AOI-1 DUC 較弱
B7: 實驗4（25片） | C7: AOI-1 系統性比 AOI-2 高 8.7%（8/20）/ 14.2%（8/21） 低粒子片差 +10~27%、高粒子片僅 +3~7% | D7: 像「每次多留一些未吹掉的微塵」，低粒子片最明顯
B8: 廠商確認 | C8: AOI-1 電磁閥規格不同、流量較小 | D8: 與上述數據方向一致
A9: 二、實驗架構
B10: 部分 | C10: 要回答的問題 | D10: 用哪些片 | E10: 做法摘要 | F10: 約需時間
B11: DUC 清潔力比對 | C11: 兩台 DUC 吹掉顆粒的能力是否一致 | D11: 「新片」12 片（從未上過 AOI） 低/中/高粒子各 4 片 | E11: 先 DUC 關量（偵測比對）→ 再 DUC 開交叉清潔（6 片 AOI-1 先吹、6 片 AOI-2 先吹） | F11: 約 1 天
B12: ★ 為什麼 一定要用「新片」：已被 DUC 吹過多次、鬆散微塵早已吹光（重複量測只差 1%），再吹也看不出清潔力差異；必須用從未上過 AOI 的片子，才有可被吹掉的顆粒。
A13: 三、實驗流程（DUC 清潔力交叉比對）
B14: 步驟0 選片 | C14: 取一盒（約 25~30 片）從未上過 AOI 的新片，以「DUC 關」在 AOI-2、AOI-1 各量 1 次，依兩台平均值分級（綜合分級）：低 50~150、中 250~600、高 ≥800，每級挑 4 片共 12 片。兩台差異 ≥10% 時自動標紅，照常記錄不重量，由品管課及工程部判定。此次 AOI-2、AOI-1 量測值直接作為步驟1 的 AOI-2①、AOI-1① 紀錄。
B15: 步驟0 分組 | C15: 每級 4 片依平均值排序，第1、4片→G1（AOI-1 先吹），第2、3片→G2（AOI-2 先吹），使兩組粒子數相當。填入「B_選片」分頁。
B16: 步驟1 DUC關 | C16: 兩台都關 DUC，12 片依 AOI-2① → AOI-1① → AOI-1② → AOI-2② 順序（共 4 趟）；①兩趟沿用步驟0 選片量測值（自動帶入），只需再量 AOI-1② → AOI-2②。目的：比偵測差、建立每片「未清潔」基準。
B17: 步驟2 DUC開 | C17: 兩台都開 DUC，每片各吹 1 次共 3 趟：G1 AOI-1 → AOI-2 → AOI-1；G2 AOI-2 → AOI-1 → AOI-2。兩組可同時在兩台跑再對調。
B18: 判讀邏輯 | C18: 第1趟＝先吹機台首道清潔效果；第2趟換另一台，若明顯再變少＝另一台吹得掉先吹機台留下的顆粒（交叉殘留去除率）；第3趟回先吹機台，看是否還能再吹掉（回吹去除率）。第2趟為另一台讀值，計算前依該片 DUC 關時兩台讀值比換算成先吹機台尺度，以排除兩台偵測差。
A19: 四、判定基準（建議值，可與廠商協議調整）
B20: 代號 | C20: 指標 | D20: 換閥前 | E20: 合格基準
B21: B1 | C21: DUC 關時兩台偵測差（12片平均） | D21: −4.7% / +4.7%（2片） | E21: |差| ≤ 5%
B22: B2 | C22: 首道清潔去除率差（AOI-1 vs AOI-2） | D22: 約 26% vs 41%（不同片） | E22: 差 ≤ 5 個百分點
B23: B3 | C23: 交叉殘留去除率（後吹機台再吹掉的比例） | D23: AOI-2 後吹 10%；AOI-1 後吹 1% | E23: 兩方向皆 ≤ 5%
B24: 全部合格 → 建議第22項「機台差異性」改判合格；B3 不合格 → 代表清潔力仍不一致，需請廠商再調氣量。
A25: 五、執行注意事項
B26: ● 實驗前請廠商提供兩台 DUC 實測氣量／壓力值與電磁閥料號（換閥後），並確認兩台 DUC 軟體參數（吹氣時間、壓力設定）相同——這是最直接的工程證據。
B27: ● 每次開工先用 2~3 片陪測片各跑一次暖機，不計入數據（避開穩定性實驗中的首日／首讀效應）。
B28: ● 全程使用同一個量測配方（TEST）、同一位人員，盡量同一天完成同一步驟；記錄每筆「耗時」以便抓異常（例：先前出現過 728 秒的異常掃描）。
B29: ● 新片「一旦開 DUC 吹過就不能再當新片」：步驟1（DUC 關）務必在步驟2 之前完成，順序不可顛倒。
B30: ● 若電磁閥尚未安裝，強烈建議先用另一批新片（可精簡為 6 片）跑一次本實驗作「換閥前基準」，換閥後再跑一次，前後比較最有說服力。
B31: ● 原始資料請依現行方式存放（機台 OutputList.csv），紀錄表只需填缺陷總數，分析由工程部完成。

Sheet B_選片
A1: 步驟0：新片篩選與分組
A2: 新片（從未上過 AOI）以 DUC 關在 AOI-2、AOI-1 各量 1 次，分別填 D、E 欄。依兩台平均值判定綜合分級：低 50~150、中 250~600、高 ≥800；兩台差異 ≥10% 時該列標紅，照常記錄、不重量。每級選 4 片，依平均值排序後 第1、4片→G1（AOI-1 先吹），第2、3片→G2（AOI-2 先吹）。
B3: No | C3: 刻號 | D3: DUC關 篩選值 AOI-1 | E3: DUC開 篩選值 AOI-2 | F3: 分級 AOI-1 | G3: 分級 AOI-2 | H3: 平均值 (AOI-1,2) | I3: 兩邊差異 % | J3: 綜合分級 | K3: 組別 | L3: 備註 | N3: 差異警示門檻 | O3: 0.1
B4: 1 | C4: 7X4HL05771A7 | E4: 603 | F4: =IF(D4="","",IF(D4>=800,"高",IF(D4>=250,IF(D4<=600,"中","—"),IF(D4>=50,IF(D4<=150,"低","—"),"—")))) | G4: =IF(E4="","",IF(E4>=800,"高",IF(E4>=250,IF(E4<=600,"中","—"),IF(E4>=50,IF(E4<=150,"低","—"),"—")))) -> — | H4: =IF(OR(D4="",E4=""),"",AVERAGE(D4,E4)) | I4: =IF(OR(H4="",H4=0),"",ABS(D4-E4)/H4) | J4: =IF(H4="","",IF(H4>=800,"高",IF(H4>=250,IF(H4<=600,"中","—"),IF(H4>=50,IF(H4<=150,"低","—"),"—")))) | K4: G1 | L4: 中-4 | N4: 差異%＝|AOI-1−AOI-2| ÷ 平均值；達門檻（≥）時該列 D~J 標紅。可改 O3。
B5: 2 | C5: 7X4HL05770B4 | E5: 839 | F5: =IF(D5="","",IF(D5>=800,"高",IF(D5>=250,IF(D5<=600,"中","—"),IF(D5>=50,IF(D5<=150,"低","—"),"—")))) | G5: =IF(E5="","",IF(E5>=800,"高",IF(E5>=250,IF(E5<=600,"中","—"),IF(E5>=50,IF(E5<=150,"低","—"),"—")))) -> 高 | H5: =IF(OR(D5="",E5=""),"",AVERAGE(D5,E5)) | I5: =IF(OR(H5="",H5=0),"",ABS(D5-E5)/H5) | J5: =IF(H5="","",IF(H5>=800,"高",IF(H5>=250,IF(H5<=600,"中","—"),IF(H5>=50,IF(H5<=150,"低","—"),"—")))) | K5: X
B6: 3 | C6: 7X4HL05772A2 | E6: 919 | F6: =IF(D6="","",IF(D6>=800,"高",IF(D6>=250,IF(D6<=600,"中","—"),IF(D6>=50,IF(D6<=150,"低","—"),"—")))) | G6: =IF(E6="","",IF(E6>=800,"高",IF(E6>=250,IF(E6<=600,"中","—"),IF(E6>=50,IF(E6<=150,"低","—"),"—")))) -> 高 | H6: =IF(OR(D6="",E6=""),"",AVERAGE(D6,E6)) | I6: =IF(OR(H6="",H6=0),"",ABS(D6-E6)/H6) | J6: =IF(H6="","",IF(H6>=800,"高",IF(H6>=250,IF(H6<=600,"中","—"),IF(H6>=50,IF(H6<=150,"低","—"),"—")))) | K6: X
B7: 4 | C7: 7X4HL05787G7 | E7: 582 | F7: =IF(D7="","",IF(D7>=800,"高",IF(D7>=250,IF(D7<=600,"中","—"),IF(D7>=50,IF(D7<=150,"低","—"),"—")))) | G7: =IF(E7="","",IF(E7>=800,"高",IF(E7>=250,IF(E7<=600,"中","—"),IF(E7>=50,IF(E7<=150,"低","—"),"—")))) -> 中 | H7: =IF(OR(D7="",E7=""),"",AVERAGE(D7,E7)) | I7: =IF(OR(H7="",H7=0),"",ABS(D7-E7)/H7) | J7: =IF(H7="","",IF(H7>=800,"高",IF(H7>=250,IF(H7<=600,"中","—"),IF(H7>=50,IF(H7<=150,"低","—"),"—")))) | K7: G2 | L7: 中-3
B8: 5 | C8: 7X4HL05788G2 | E8: 602 | F8: =IF(D8="","",IF(D8>=800,"高",IF(D8>=250,IF(D8<=600,"中","—"),IF(D8>=50,IF(D8<=150,"低","—"),"—")))) | G8: =IF(E8="","",IF(E8>=800,"高",IF(E8>=250,IF(E8<=600,"中","—"),IF(E8>=50,IF(E8<=150,"低","—"),"—")))) -> — | H8: =IF(OR(D8="",E8=""),"",AVERAGE(D8,E8)) | I8: =IF(OR(H8="",H8=0),"",ABS(D8-E8)/H8) | J8: =IF(H8="","",IF(H8>=800,"高",IF(H8>=250,IF(H8<=600,"中","—"),IF(H8>=50,IF(H8<=150,"低","—"),"—")))) | K8: X
B9: 6 | C9: NKAAEB588DB2 | E9: 947 | F9: =IF(D9="","",IF(D9>=800,"高",IF(D9>=250,IF(D9<=600,"中","—"),IF(D9>=50,IF(D9<=150,"低","—"),"—")))) | G9: =IF(E9="","",IF(E9>=800,"高",IF(E9>=250,IF(E9<=600,"中","—"),IF(E9>=50,IF(E9<=150,"低","—"),"—")))) -> 高 | H9: =IF(OR(D9="",E9=""),"",AVERAGE(D9,E9)) | I9: =IF(OR(H9="",H9=0),"",ABS(D9-E9)/H9) | J9: =IF(H9="","",IF(H9>=800,"高",IF(H9>=250,IF(H9<=600,"中","—"),IF(H9>=50,IF(H9<=150,"低","—"),"—")))) | K9: X
B10: 7 | C10: NKAAEEFA77B1 | E10: 887 | F10: =IF(D10="","",IF(D10>=800,"高",IF(D10>=250,IF(D10<=600,"中","—"),IF(D10>=50,IF(D10<=150,"低","—"),"—")))) | G10: =IF(E10="","",IF(E10>=800,"高",IF(E10>=250,IF(E10<=600,"中","—"),IF(E10>=50,IF(E10<=150,"低","—"),"—")))) -> 高 | H10: =IF(OR(D10="",E10=""),"",AVERAGE(D10,E10)) | I10: =IF(OR(H10="",H10=0),"",ABS(D10-E10)/H10) | J10: =IF(H10="","",IF(H10>=800,"高",IF(H10>=250,IF(H10<=600,"中","—"),IF(H10>=50,IF(H10<=150,"低","—"),"—")))) | K10: G1 | L10: 高-1
B11: 8 | C11: NKAAEB57F7B4 | E11: 1022 | F11: =IF(D11="","",IF(D11>=800,"高",IF(D11>=250,IF(D11<=600,"中","—"),IF(D11>=50,IF(D11<=150,"低","—"),"—")))) | G11: =IF(E11="","",IF(E11>=800,"高",IF(E11>=250,IF(E11<=600,"中","—"),IF(E11>=50,IF(E11<=150,"低","—"),"—")))) -> 高 | H11: =IF(OR(D11="",E11=""),"",AVERAGE(D11,E11)) | I11: =IF(OR(H11="",H11=0),"",ABS(D11-E11)/H11) | J11: =IF(H11="","",IF(H11>=800,"高",IF(H11>=250,IF(H11<=600,"中","—"),IF(H11>=50,IF(H11<=150,"低","—"),"—")))) | K11: G2 | L11: 高-3
B12: 9 | C12: NKAAE26A4FD0 | E12: 1637 | F12: =IF(D12="","",IF(D12>=800,"高",IF(D12>=250,IF(D12<=600,"中","—"),IF(D12>=50,IF(D12<=150,"低","—"),"—")))) | G12: =IF(E12="","",IF(E12>=800,"高",IF(E12>=250,IF(E12<=600,"中","—"),IF(E12>=50,IF(E12<=150,"低","—"),"—")))) -> 高 | H12: =IF(OR(D12="",E12=""),"",AVERAGE(D12,E12)) | I12: =IF(OR(H12="",H12=0),"",ABS(D12-E12)/H12) | J12: =IF(H12="","",IF(H12>=800,"高",IF(H12>=250,IF(H12<=600,"中","—"),IF(H12>=50,IF(H12<=150,"低","—"),"—")))) | K12: X
B13: 10 | C13: NKAAEE9B78F2 | E13: 1935 | F13: =IF(D13="","",IF(D13>=800,"高",IF(D13>=250,IF(D13<=600,"中","—"),IF(D13>=50,IF(D13<=150,"低","—"),"—")))) | G13: =IF(E13="","",IF(E13>=800,"高",IF(E13>=250,IF(E13<=600,"中","—"),IF(E13>=50,IF(E13<=150,"低","—"),"—")))) -> 高 | H13: =IF(OR(D13="",E13=""),"",AVERAGE(D13,E13)) | I13: =IF(OR(H13="",H13=0),"",ABS(D13-E13)/H13) | J13: =IF(H13="","",IF(H13>=800,"高",IF(H13>=250,IF(H13<=600,"中","—"),IF(H13>=50,IF(H13<=150,"低","—"),"—")))) | K13: X
B14: 11 | C14: NKAAEEFA73D5 | E14: 1082 | F14: =IF(D14="","",IF(D14>=800,"高",IF(D14>=250,IF(D14<=600,"中","—"),IF(D14>=50,IF(D14<=150,"低","—"),"—")))) | G14: =IF(E14="","",IF(E14>=800,"高",IF(E14>=250,IF(E14<=600,"中","—"),IF(E14>=50,IF(E14<=150,"低","—"),"—")))) -> 高 | H14: =IF(OR(D14="",E14=""),"",AVERAGE(D14,E14)) | I14: =IF(OR(H14="",H14=0),"",ABS(D14-E14)/H14) | J14: =IF(H14="","",IF(H14>=800,"高",IF(H14>=250,IF(H14<=600,"中","—"),IF(H14>=50,IF(H14<=150,"低","—"),"—")))) | K14: X
B15: 12 | C15: NKAAE3342CE2 | E15: 930 | F15: =IF(D15="","",IF(D15>=800,"高",IF(D15>=250,IF(D15<=600,"中","—"),IF(D15>=50,IF(D15<=150,"低","—"),"—")))) | G15: =IF(E15="","",IF(E15>=800,"高",IF(E15>=250,IF(E15<=600,"中","—"),IF(E15>=50,IF(E15<=150,"低","—"),"—")))) -> 高 | H15: =IF(OR(D15="",E15=""),"",AVERAGE(D15,E15)) | I15: =IF(OR(H15="",H15=0),"",ABS(D15-E15)/H15) | J15: =IF(H15="","",IF(H15>=800,"高",IF(H15>=250,IF(H15<=600,"中","—"),IF(H15>=50,IF(H15<=150,"低","—"),"—")))) | K15: G2 | L15: 高-2
B16: 13 | C16: NKAAE238E5C2 | E16: 1099 | F16: =IF(D16="","",IF(D16>=800,"高",IF(D16>=250,IF(D16<=600,"中","—"),IF(D16>=50,IF(D16<=150,"低","—"),"—")))) | G16: =IF(E16="","",IF(E16>=800,"高",IF(E16>=250,IF(E16<=600,"中","—"),IF(E16>=50,IF(E16<=150,"低","—"),"—")))) -> 高 | H16: =IF(OR(D16="",E16=""),"",AVERAGE(D16,E16)) | I16: =IF(OR(H16="",H16=0),"",ABS(D16-E16)/H16) | J16: =IF(H16="","",IF(H16>=800,"高",IF(H16>=250,IF(H16<=600,"中","—"),IF(H16>=50,IF(H16<=150,"低","—"),"—")))) | K16: X
B17: 14 | C17: NKAAE26A3BD1 | E17: 845 | F17: =IF(D17="","",IF(D17>=800,"高",IF(D17>=250,IF(D17<=600,"中","—"),IF(D17>=50,IF(D17<=150,"低","—"),"—")))) | G17: =IF(E17="","",IF(E17>=800,"高",IF(E17>=250,IF(E17<=600,"中","—"),IF(E17>=50,IF(E17<=150,"低","—"),"—")))) -> 高 | H17: =IF(OR(D17="",E17=""),"",AVERAGE(D17,E17)) | I17: =IF(OR(H17="",H17=0),"",ABS(D17-E17)/H17) | J17: =IF(H17="","",IF(H17>=800,"高",IF(H17>=250,IF(H17<=600,"中","—"),IF(H17>=50,IF(H17<=150,"低","—"),"—")))) | K17: X
B18: 15 | C18: NKAAEED984G5 | E18: 1081 | F18: =IF(D18="","",IF(D18>=800,"高",IF(D18>=250,IF(D18<=600,"中","—"),IF(D18>=50,IF(D18<=150,"低","—"),"—")))) | G18: =IF(E18="","",IF(E18>=800,"高",IF(E18>=250,IF(E18<=600,"中","—"),IF(E18>=50,IF(E18<=150,"低","—"),"—")))) -> 高 | H18: =IF(OR(D18="",E18=""),"",AVERAGE(D18,E18)) | I18: =IF(OR(H18="",H18=0),"",ABS(D18-E18)/H18) | J18: =IF(H18="","",IF(H18>=800,"高",IF(H18>=250,IF(H18<=600,"中","—"),IF(H18>=50,IF(H18<=150,"低","—"),"—")))) | K18: X
B19: 16 | C19: NKAAEEB3AFE3 | E19: 1620 | F19: =IF(D19="","",IF(D19>=800,"高",IF(D19>=250,IF(D19<=600,"中","—"),IF(D19>=50,IF(D19<=150,"低","—"),"—")))) | G19: =IF(E19="","",IF(E19>=800,"高",IF(E19>=250,IF(E19<=600,"中","—"),IF(E19>=50,IF(E19<=150,"低","—"),"—")))) -> 高 | H19: =IF(OR(D19="",E19=""),"",AVERAGE(D19,E19)) | I19: =IF(OR(H19="",H19=0),"",ABS(D19-E19)/H19) | J19: =IF(H19="","",IF(H19>=800,"高",IF(H19>=250,IF(H19<=600,"中","—"),IF(H19>=50,IF(H19<=150,"低","—"),"—")))) | K19: X
B20: 17 | C20: NKAAECF1DBD1 | E20: 1513 | F20: =IF(D20="","",IF(D20>=800,"高",IF(D20>=250,IF(D20<=600,"中","—"),IF(D20>=50,IF(D20<=150,"低","—"),"—")))) | G20: =IF(E20="","",IF(E20>=800,"高",IF(E20>=250,IF(E20<=600,"中","—"),IF(E20>=50,IF(E20<=150,"低","—"),"—")))) -> 高 | H20: =IF(OR(D20="",E20=""),"",AVERAGE(D20,E20)) | I20: =IF(OR(H20="",H20=0),"",ABS(D20-E20)/H20) | J20: =IF(H20="","",IF(H20>=800,"高",IF(H20>=250,IF(H20<=600,"中","—"),IF(H20>=50,IF(H20<=150,"低","—"),"—")))) | K20: X
B21: 18 | C21: NKAAEEFA95H1 | E21: 1242 | F21: =IF(D21="","",IF(D21>=800,"高",IF(D21>=250,IF(D21<=600,"中","—"),IF(D21>=50,IF(D21<=150,"低","—"),"—")))) | G21: =IF(E21="","",IF(E21>=800,"高",IF(E21>=250,IF(E21<=600,"中","—"),IF(E21>=50,IF(E21<=150,"低","—"),"—")))) -> 高 | H21: =IF(OR(D21="",E21=""),"",AVERAGE(D21,E21)) | I21: =IF(OR(H21="",H21=0),"",ABS(D21-E21)/H21) | J21: =IF(H21="","",IF(H21>=800,"高",IF(H21>=250,IF(H21<=600,"中","—"),IF(H21>=50,IF(H21<=150,"低","—"),"—")))) | K21: X
B22: 19 | C22: NKAAEEFA93B0 | E22: 1039 | F22: =IF(D22="","",IF(D22>=800,"高",IF(D22>=250,IF(D22<=600,"中","—"),IF(D22>=50,IF(D22<=150,"低","—"),"—")))) | G22: =IF(E22="","",IF(E22>=800,"高",IF(E22>=250,IF(E22<=600,"中","—"),IF(E22>=50,IF(E22<=150,"低","—"),"—")))) -> 高 | H22: =IF(OR(D22="",E22=""),"",AVERAGE(D22,E22)) | I22: =IF(OR(H22="",H22=0),"",ABS(D22-E22)/H22) | J22: =IF(H22="","",IF(H22>=800,"高",IF(H22>=250,IF(H22<=600,"中","—"),IF(H22>=50,IF(H22<=150,"低","—"),"—")))) | K22: X
B23: 20 | C23: NKAAEEDE77B6 | E23: 1292 | F23: =IF(D23="","",IF(D23>=800,"高",IF(D23>=250,IF(D23<=600,"中","—"),IF(D23>=50,IF(D23<=150,"低","—"),"—")))) | G23: =IF(E23="","",IF(E23>=800,"高",IF(E23>=250,IF(E23<=600,"中","—"),IF(E23>=50,IF(E23<=150,"低","—"),"—")))) -> 高 | H23: =IF(OR(D23="",E23=""),"",AVERAGE(D23,E23)) | I23: =IF(OR(H23="",H23=0),"",ABS(D23-E23)/H23) | J23: =IF(H23="","",IF(H23>=800,"高",IF(H23>=250,IF(H23<=600,"中","—"),IF(H23>=50,IF(H23<=150,"低","—"),"—")))) | K23: X
B24: 21 | C24: NKAAEEB8D4H1 | E24: 1984 | F24: =IF(D24="","",IF(D24>=800,"高",IF(D24>=250,IF(D24<=600,"中","—"),IF(D24>=50,IF(D24<=150,"低","—"),"—")))) | G24: =IF(E24="","",IF(E24>=800,"高",IF(E24>=250,IF(E24<=600,"中","—"),IF(E24>=50,IF(E24<=150,"低","—"),"—")))) -> 高 | H24: =IF(OR(D24="",E24=""),"",AVERAGE(D24,E24)) | I24: =IF(OR(H24="",H24=0),"",ABS(D24-E24)/H24) | J24: =IF(H24="","",IF(H24>=800,"高",IF(H24>=250,IF(H24<=600,"中","—"),IF(H24>=50,IF(H24<=150,"低","—"),"—")))) | K24: X
B25: 22 | C25: NKAAEEFA90C7 | E25: 1544 | F25: =IF(D25="","",IF(D25>=800,"高",IF(D25>=250,IF(D25<=600,"中","—"),IF(D25>=50,IF(D25<=150,"低","—"),"—")))) | G25: =IF(E25="","",IF(E25>=800,"高",IF(E25>=250,IF(E25<=600,"中","—"),IF(E25>=50,IF(E25<=150,"低","—"),"—")))) -> 高 | H25: =IF(OR(D25="",E25=""),"",AVERAGE(D25,E25)) | I25: =IF(OR(H25="",H25=0),"",ABS(D25-E25)/H25) | J25: =IF(H25="","",IF(H25>=800,"高",IF(H25>=250,IF(H25<=600,"中","—"),IF(H25>=50,IF(H25<=150,"低","—"),"—")))) | K25: X
B26: 23 | C26: NKAAEDA95AA7 | E26: 1661 | F26: =IF(D26="","",IF(D26>=800,"高",IF(D26>=250,IF(D26<=600,"中","—"),IF(D26>=50,IF(D26<=150,"低","—"),"—")))) | G26: =IF(E26="","",IF(E26>=800,"高",IF(E26>=250,IF(E26<=600,"中","—"),IF(E26>=50,IF(E26<=150,"低","—"),"—")))) -> 高 | H26: =IF(OR(D26="",E26=""),"",AVERAGE(D26,E26)) | I26: =IF(OR(H26="",H26=0),"",ABS(D26-E26)/H26) | J26: =IF(H26="","",IF(H26>=800,"高",IF(H26>=250,IF(H26<=600,"中","—"),IF(H26>=50,IF(H26<=150,"低","—"),"—")))) | K26: X
B27: 24 | C27: NKAAEEB098D4 | E27: 1321 | F27: =IF(D27="","",IF(D27>=800,"高",IF(D27>=250,IF(D27<=600,"中","—"),IF(D27>=50,IF(D27<=150,"低","—"),"—")))) | G27: =IF(E27="","",IF(E27>=800,"高",IF(E27>=250,IF(E27<=600,"中","—"),IF(E27>=50,IF(E27<=150,"低","—"),"—")))) -> 高 | H27: =IF(OR(D27="",E27=""),"",AVERAGE(D27,E27)) | I27: =IF(OR(H27="",H27=0),"",ABS(D27-E27)/H27) | J27: =IF(H27="","",IF(H27>=800,"高",IF(H27>=250,IF(H27<=600,"中","—"),IF(H27>=50,IF(H27<=150,"低","—"),"—")))) | K27: X
B28: 25 | C28: NKAAEE96DAB5 | E28: 1035 | F28: =IF(D28="","",IF(D28>=800,"高",IF(D28>=250,IF(D28<=600,"中","—"),IF(D28>=50,IF(D28<=150,"低","—"),"—")))) | G28: =IF(E28="","",IF(E28>=800,"高",IF(E28>=250,IF(E28<=600,"中","—"),IF(E28>=50,IF(E28<=150,"低","—"),"—")))) -> 高 | H28: =IF(OR(D28="",E28=""),"",AVERAGE(D28,E28)) | I28: =IF(OR(H28="",H28=0),"",ABS(D28-E28)/H28) | J28: =IF(H28="","",IF(H28>=800,"高",IF(H28>=250,IF(H28<=600,"中","—"),IF(H28>=50,IF(H28<=150,"低","—"),"—")))) | K28: G1 | L28: 高-4
B29: 26 | C29: 7X4EH05630G6 | E29: 48 | F29: =IF(D29="","",IF(D29>=800,"高",IF(D29>=250,IF(D29<=600,"中","—"),IF(D29>=50,IF(D29<=150,"低","—"),"—")))) | G29: =IF(E29="","",IF(E29>=800,"高",IF(E29>=250,IF(E29<=600,"中","—"),IF(E29>=50,IF(E29<=150,"低","—"),"—")))) -> — | H29: =IF(OR(D29="",E29=""),"",AVERAGE(D29,E29)) | I29: =IF(OR(H29="",H29=0),"",ABS(D29-E29)/H29) | J29: =IF(H29="","",IF(H29>=800,"高",IF(H29>=250,IF(H29<=600,"中","—"),IF(H29>=50,IF(H29<=150,"低","—"),"—")))) | K29: G2 | L29: 低-2
B30: 27 | C30: 7X4EH05897D0 | E30: 105 | F30: =IF(D30="","",IF(D30>=800,"高",IF(D30>=250,IF(D30<=600,"中","—"),IF(D30>=50,IF(D30<=150,"低","—"),"—")))) | G30: =IF(E30="","",IF(E30>=800,"高",IF(E30>=250,IF(E30<=600,"中","—"),IF(E30>=50,IF(E30<=150,"低","—"),"—")))) -> 低 | H30: =IF(OR(D30="",E30=""),"",AVERAGE(D30,E30)) | I30: =IF(OR(H30="",H30=0),"",ABS(D30-E30)/H30) | J30: =IF(H30="","",IF(H30>=800,"高",IF(H30>=250,IF(H30<=600,"中","—"),IF(H30>=50,IF(H30<=150,"低","—"),"—")))) | K30: X
B31: 28 | C31: 7X4EL07303C7 | E31: 200 | F31: =IF(D31="","",IF(D31>=800,"高",IF(D31>=250,IF(D31<=600,"中","—"),IF(D31>=50,IF(D31<=150,"低","—"),"—")))) | G31: =IF(E31="","",IF(E31>=800,"高",IF(E31>=250,IF(E31<=600,"中","—"),IF(E31>=50,IF(E31<=150,"低","—"),"—")))) -> — | H31: =IF(OR(D31="",E31=""),"",AVERAGE(D31,E31)) | I31: =IF(OR(H31="",H31=0),"",ABS(D31-E31)/H31) | J31: =IF(H31="","",IF(H31>=800,"高",IF(H31>=250,IF(H31<=600,"中","—"),IF(H31>=50,IF(H31<=150,"低","—"),"—")))) | K31: X
B32: 29 | C32: 7X4EH05880F0 | E32: 131 | F32: =IF(D32="","",IF(D32>=800,"高",IF(D32>=250,IF(D32<=600,"中","—"),IF(D32>=50,IF(D32<=150,"低","—"),"—")))) | G32: =IF(E32="","",IF(E32>=800,"高",IF(E32>=250,IF(E32<=600,"中","—"),IF(E32>=50,IF(E32<=150,"低","—"),"—")))) -> 低 | H32: =IF(OR(D32="",E32=""),"",AVERAGE(D32,E32)) | I32: =IF(OR(H32="",H32=0),"",ABS(D32-E32)/H32) | J32: =IF(H32="","",IF(H32>=800,"高",IF(H32>=250,IF(H32<=600,"中","—"),IF(H32>=50,IF(H32<=150,"低","—"),"—")))) | K32: G1 | L32: 低-4
B33: 30 | C33: 7X4EH05883D1 | E33: 81 | F33: =IF(D33="","",IF(D33>=800,"高",IF(D33>=250,IF(D33<=600,"中","—"),IF(D33>=50,IF(D33<=150,"低","—"),"—")))) | G33: =IF(E33="","",IF(E33>=800,"高",IF(E33>=250,IF(E33<=600,"中","—"),IF(E33>=50,IF(E33<=150,"低","—"),"—")))) -> 低 | H33: =IF(OR(D33="",E33=""),"",AVERAGE(D33,E33)) | I33: =IF(OR(H33="",H33=0),"",ABS(D33-E33)/H33) | J33: =IF(H33="","",IF(H33>=800,"高",IF(H33>=250,IF(H33<=600,"中","—"),IF(H33>=50,IF(H33<=150,"低","—"),"—")))) | K33: X
B34: 31 | C34: 7X4HL05776F1 | E34: 113 | F34: =IF(D34="","",IF(D34>=800,"高",IF(D34>=250,IF(D34<=600,"中","—"),IF(D34>=50,IF(D34<=150,"低","—"),"—")))) | G34: =IF(E34="","",IF(E34>=800,"高",IF(E34>=250,IF(E34<=600,"中","—"),IF(E34>=50,IF(E34<=150,"低","—"),"—")))) -> 低 | H34: =IF(OR(D34="",E34=""),"",AVERAGE(D34,E34)) | I34: =IF(OR(H34="",H34=0),"",ABS(D34-E34)/H34) | J34: =IF(H34="","",IF(H34>=800,"高",IF(H34>=250,IF(H34<=600,"中","—"),IF(H34>=50,IF(H34<=150,"低","—"),"—")))) | K34: X
B35: 32 | C35: 7X4HH11449H2 | E35: 3615 | F35: =IF(D35="","",IF(D35>=800,"高",IF(D35>=250,IF(D35<=600,"中","—"),IF(D35>=50,IF(D35<=150,"低","—"),"—")))) | G35: =IF(E35="","",IF(E35>=800,"高",IF(E35>=250,IF(E35<=600,"中","—"),IF(E35>=50,IF(E35<=150,"低","—"),"—")))) -> 高 | H35: =IF(OR(D35="",E35=""),"",AVERAGE(D35,E35)) | I35: =IF(OR(H35="",H35=0),"",ABS(D35-E35)/H35) | J35: =IF(H35="","",IF(H35>=800,"高",IF(H35>=250,IF(H35<=600,"中","—"),IF(H35>=50,IF(H35<=150,"低","—"),"—")))) | K35: X
B36: 33 | C36: 7X4EL07479F2 | E36: 85 | F36: =IF(D36="","",IF(D36>=800,"高",IF(D36>=250,IF(D36<=600,"中","—"),IF(D36>=50,IF(D36<=150,"低","—"),"—")))) | G36: =IF(E36="","",IF(E36>=800,"高",IF(E36>=250,IF(E36<=600,"中","—"),IF(E36>=50,IF(E36<=150,"低","—"),"—")))) -> 低 | H36: =IF(OR(D36="",E36=""),"",AVERAGE(D36,E36)) | I36: =IF(OR(H36="",H36=0),"",ABS(D36-E36)/H36) | J36: =IF(H36="","",IF(H36>=800,"高",IF(H36>=250,IF(H36<=600,"中","—"),IF(H36>=50,IF(H36<=150,"低","—"),"—")))) | K36: G2 | L36: 低-3
B37: 34 | C37: 7X4EH05872B3 | E37: 260 | F37: =IF(D37="","",IF(D37>=800,"高",IF(D37>=250,IF(D37<=600,"中","—"),IF(D37>=50,IF(D37<=150,"低","—"),"—")))) | G37: =IF(E37="","",IF(E37>=800,"高",IF(E37>=250,IF(E37<=600,"中","—"),IF(E37>=50,IF(E37<=150,"低","—"),"—")))) -> 中 | H37: =IF(OR(D37="",E37=""),"",AVERAGE(D37,E37)) | I37: =IF(OR(H37="",H37=0),"",ABS(D37-E37)/H37) | J37: =IF(H37="","",IF(H37>=800,"高",IF(H37>=250,IF(H37<=600,"中","—"),IF(H37>=50,IF(H37<=150,"低","—"),"—")))) | K37: G1 | L37: 中-1
B38: 35 | C38: 7X4EH05896D5 | E38: 160 | F38: =IF(D38="","",IF(D38>=800,"高",IF(D38>=250,IF(D38<=600,"中","—"),IF(D38>=50,IF(D38<=150,"低","—"),"—")))) | G38: =IF(E38="","",IF(E38>=800,"高",IF(E38>=250,IF(E38<=600,"中","—"),IF(E38>=50,IF(E38<=150,"低","—"),"—")))) -> — | H38: =IF(OR(D38="",E38=""),"",AVERAGE(D38,E38)) | I38: =IF(OR(H38="",H38=0),"",ABS(D38-E38)/H38) | J38: =IF(H38="","",IF(H38>=800,"高",IF(H38>=250,IF(H38<=600,"中","—"),IF(H38>=50,IF(H38<=150,"低","—"),"—")))) | K38: X
B39: 36 | C39: 7X4EH05876G2 | E39: 104 | F39: =IF(D39="","",IF(D39>=800,"高",IF(D39>=250,IF(D39<=600,"中","—"),IF(D39>=50,IF(D39<=150,"低","—"),"—")))) | G39: =IF(E39="","",IF(E39>=800,"高",IF(E39>=250,IF(E39<=600,"中","—"),IF(E39>=50,IF(E39<=150,"低","—"),"—")))) -> 低 | H39: =IF(OR(D39="",E39=""),"",AVERAGE(D39,E39)) | I39: =IF(OR(H39="",H39=0),"",ABS(D39-E39)/H39) | J39: =IF(H39="","",IF(H39>=800,"高",IF(H39>=250,IF(H39<=600,"中","—"),IF(H39>=50,IF(H39<=150,"低","—"),"—")))) | K39: X
B40: 37 | C40: 7X4EL07304C2 | E40: 40 | F40: =IF(D40="","",IF(D40>=800,"高",IF(D40>=250,IF(D40<=600,"中","—"),IF(D40>=50,IF(D40<=150,"低","—"),"—")))) | G40: =IF(E40="","",IF(E40>=800,"高",IF(E40>=250,IF(E40<=600,"中","—"),IF(E40>=50,IF(E40<=150,"低","—"),"—")))) -> — | H40: =IF(OR(D40="",E40=""),"",AVERAGE(D40,E40)) | I40: =IF(OR(H40="",H40=0),"",ABS(D40-E40)/H40) | J40: =IF(H40="","",IF(H40>=800,"高",IF(H40>=250,IF(H40<=600,"中","—"),IF(H40>=50,IF(H40<=150,"低","—"),"—")))) | K40: G1 | L40: 低-1
...

Sheet C_清潔力紀錄
A1: 步驟1~2：DUC 清潔力交叉比對紀錄
A2: 步驟1（兩台 DUC 關）只需填刻號；分級（綜合分級）及 AOI-2①、AOI-1① 由「B_選片」依刻號自動帶入（綠字，免填）；現場只需再量 AOI-1② → AOI-2②。步驟2（兩台 DUC 開）每片各吹 1 次共 3 趟：G1 AOI-1 → AOI-2 → AOI-1；G2 AOI-2 → AOI-1 → AOI-2，依序填第1、2、3趟。黃底填缺陷總數，右側自動計算。
B3: No | C3: 刻號 | D3: 分級 | E3: 組別 | F3: 第1趟 機台 | G3: DUC開 AOI-2① | H3: DUC關 AOI-1① | I3: DUC關 AOI-1② | J3: DUC關 AOI-2② | K3: DUC開 第1趟 | L3: DUC開 第2趟 | M3: 第2趟 機台 | N3: DUC開 第3趟 | O3: 第3趟 機台 | P3: 第2趟 校正值 | Q3: 偵測差% (1−2)/2 | R3: 首道 去除率 | S3: 交叉殘留 去除率 | T3: 回吹 去除率
B4: 1 | C4: 7X4EL07304C2 | D4: 低 | E4: G1 | F4: =IF(E4="G1","AOI-1",IF(E4="G2","AOI-2","")) -> AOI-1 | G4: 40 | I4: 3185 | J4: 2969 | K4: 1677 | L4: 1454 | M4: =IF(F4="AOI-1","AOI-2",IF(F4="AOI-2","AOI-1","")) -> AOI-2 | N4: 1557 | O4: AOI-1 | P4: =IF(OR(L4="",COUNT(G4:J4)<4),"",IF(F4="AOI-1",L4*AVERAGE(H4,I4)/AVERAGE(G4,J4),L4*AVERAGE(G4,J4)/AVERAGE(H4,I4))) | Q4: =IF(COUNT(G4:J4)<4,"",(AVERAGE(H4,I4)-AVERAGE(G4,J4))/AVERAGE(G4,J4)) | R4: =IF(OR(K4="",COUNT(G4:J4)<4),"",IF(F4="AOI-1",(AVERAGE(H4,I4)-K4)/AVERAGE(H4,I4),(AVERAGE(G4,J4)-K4)/AVERAGE(G4,J4))) | S4: =IF(OR(K4="",P4=""),"",(K4-P4)/K4) | T4: =IF(OR(P4="",#REF!=""),"",(P4-#REF!)/P4) -> #REF!
B5: 2 | C5: 7X4EH05630G6 | D5: 低 | E5: G2 | F5: =IF(E5="G1","AOI-1",IF(E5="G2","AOI-2","")) -> AOI-2 | G5: =IF(C5="","",IFERROR(IF(INDEX(B_選片!$E$4:$E$33,MATCH(C5,B_選片!$C$4:$C$33,0))="","",INDEX(B_選片!$E$4:$E$33,MATCH(C5,B_選片!$C$4:$C$33,0))),"查無")) -> 48 | I5: 1718 | J5: 1727 | K5: 330 | L5: 386 | M5: =IF(F5="AOI-1","AOI-2",IF(F5="AOI-2","AOI-1","")) -> AOI-1 | N5: 314 | O5: AOI-2 | P5: =IF(OR(L5="",COUNT(G5:J5)<4),"",IF(F5="AOI-1",L5*AVERAGE(H5,I5)/AVERAGE(G5,J5),L5*AVERAGE(G5,J5)/AVERAGE(H5,I5))) | Q5: =IF(COUNT(G5:J5)<4,"",(AVERAGE(H5,I5)-AVERAGE(G5,J5))/AVERAGE(G5,J5)) | R5: =IF(OR(K5="",COUNT(G5:J5)<4),"",IF(F5="AOI-1",(AVERAGE(H5,I5)-K5)/AVERAGE(H5,I5),(AVERAGE(G5,J5)-K5)/AVERAGE(G5,J5))) | S5: =IF(OR(K5="",P5=""),"",(K5-P5)/K5) | T5: =IF(OR(P5="",#REF!=""),"",(P5-#REF!)/P5) -> #REF!
B7: 3 | C7: 7X4EH05880F0 | D7: 低 | E7: G1 | F7: =IF(E7="G1","AOI-1",IF(E7="G2","AOI-2","")) -> AOI-1 | G7: =IF(C7="","",IFERROR(IF(INDEX(B_選片!$E$4:$E$33,MATCH(C7,B_選片!$C$4:$C$33,0))="","",INDEX(B_選片!$E$4:$E$33,MATCH(C7,B_選片!$C$4:$C$33,0))),"查無")) -> 131 | I7: 4186 | J7: 3933 | K7: 1677 | L7: 1410 | M7: =IF(F7="AOI-1","AOI-2",IF(F7="AOI-2","AOI-1","")) -> AOI-2 | N7: 1538 | O7: AOI-1 | P7: =IF(OR(L7="",COUNT(G7:J7)<4),"",IF(F7="AOI-1",L7*AVERAGE(H7,I7)/AVERAGE(G7,J7),L7*AVERAGE(G7,J7)/AVERAGE(H7,I7))) | Q7: =IF(COUNT(G7:J7)<4,"",(AVERAGE(H7,I7)-AVERAGE(G7,J7))/AVERAGE(G7,J7)) | R7: =IF(OR(K7="",COUNT(G7:J7)<4),"",IF(F7="AOI-1",(AVERAGE(H7,I7)-K7)/AVERAGE(H7,I7),(AVERAGE(G7,J7)-K7)/AVERAGE(G7,J7))) | S7: =IF(OR(K7="",P7=""),"",(K7-P7)/K7) | T7: =IF(OR(P7="",#REF!=""),"",(P7-#REF!)/P7) -> #REF!
B8: 4 | C8: 7X4EL07479F2 | D8: 低 | E8: G2 | F8: =IF(E8="G1","AOI-1",IF(E8="G2","AOI-2","")) -> AOI-2 | G8: 85 | I8: 3882 | J8: 3735 | K8: 884 | L8: 977 | M8: =IF(F8="AOI-1","AOI-2",IF(F8="AOI-2","AOI-1","")) -> AOI-1 | N8: 831 | O8: AOI-2 | P8: =IF(OR(L8="",COUNT(G8:J8)<4),"",IF(F8="AOI-1",L8*AVERAGE(H8,I8)/AVERAGE(G8,J8),L8*AVERAGE(G8,J8)/AVERAGE(H8,I8))) | Q8: =IF(COUNT(G8:J8)<4,"",(AVERAGE(H8,I8)-AVERAGE(G8,J8))/AVERAGE(G8,J8)) | R8: =IF(OR(K8="",COUNT(G8:J8)<4),"",IF(F8="AOI-1",(AVERAGE(H8,I8)-K8)/AVERAGE(H8,I8),(AVERAGE(G8,J8)-K8)/AVERAGE(G8,J8))) | S8: =IF(OR(K8="",P8=""),"",(K8-P8)/K8) | T8: =IF(OR(P8="",#REF!=""),"",(P8-#REF!)/P8) -> #REF!
B10: 5 | C10: 7X4EH05872B3 | D10: 中 | E10: G1 | F10: =IF(E10="G1","AOI-1",IF(E10="G2","AOI-2","")) -> AOI-1 | G10: 260 | I10: 4885 | J10: 4585 | K10: 1818 | L10: 1589 | M10: =IF(F10="AOI-1","AOI-2",IF(F10="AOI-2","AOI-1","")) -> AOI-2 | N10: 1734 | O10: AOI-1 | P10: =IF(OR(L10="",COUNT(G10:J10)<4),"",IF(F10="AOI-1",L10*AVERAGE(H10,I10)/AVERAGE(G10,J10),L10*AVERAGE(G10,J10)/AVERAGE(H10,I10))) | Q10: =IF(COUNT(G10:J10)<4,"",(AVERAGE(H10,I10)-AVERAGE(G10,J10))/AVERAGE(G10,J10)) | R10: =IF(OR(K10="",COUNT(G10:J10)<4),"",IF(F10="AOI-1",(AVERAGE(H10,I10)-K10)/AVERAGE(H10,I10),(AVERAGE(G10,J10)-K10)/AVERAGE(G10,J10))) | S10: =IF(OR(K10="",P10=""),"",(K10-P10)/K10) | T10: =IF(OR(P10="",#REF!=""),"",(P10-#REF!)/P10) -> #REF!
B11: 6 | C11: NKAAEEFA75C3 | D11: 中 | E11: G2 | F11: =IF(E11="G1","AOI-1",IF(E11="G2","AOI-2","")) -> AOI-2 | G11: 279 | I11: 3022 | J11: 2830 | K11: 819 | L11: 923 | M11: =IF(F11="AOI-1","AOI-2",IF(F11="AOI-2","AOI-1","")) -> AOI-1 | N11: 787 | O11: AOI-2 | P11: =IF(OR(L11="",COUNT(G11:J11)<4),"",IF(F11="AOI-1",L11*AVERAGE(H11,I11)/AVERAGE(G11,J11),L11*AVERAGE(G11,J11)/AVERAGE(H11,I11))) | Q11: =IF(COUNT(G11:J11)<4,"",(AVERAGE(H11,I11)-AVERAGE(G11,J11))/AVERAGE(G11,J11)) | R11: =IF(OR(K11="",COUNT(G11:J11)<4),"",IF(F11="AOI-1",(AVERAGE(H11,I11)-K11)/AVERAGE(H11,I11),(AVERAGE(G11,J11)-K11)/AVERAGE(G11,J11))) | S11: =IF(OR(K11="",P11=""),"",(K11-P11)/K11) | T11: =IF(OR(P11="",#REF!=""),"",(P11-#REF!)/P11) -> #REF!
B13: 7 | C13: 7X4HL05771A7 | D13: 中 | E13: G1 | F13: =IF(E13="G1","AOI-1",IF(E13="G2","AOI-2","")) -> AOI-1 | G13: =IF(C13="","",IFERROR(IF(INDEX(B_選片!$E$4:$E$33,MATCH(C13,B_選片!$C$4:$C$33,0))="","",INDEX(B_選片!$E$4:$E$33,MATCH(C13,B_選片!$C$4:$C$33,0))),"查無")) -> 603 | I13: 6297 | J13: 5791 | K13: 1868 | L13: 1518 | M13: =IF(F13="AOI-1","AOI-2",IF(F13="AOI-2","AOI-1","")) -> AOI-2 | N13: 1750 | O13: AOI-1 | P13: =IF(OR(L13="",COUNT(G13:J13)<4),"",IF(F13="AOI-1",L13*AVERAGE(H13,I13)/AVERAGE(G13,J13),L13*AVERAGE(G13,J13)/AVERAGE(H13,I13))) | Q13: =IF(COUNT(G13:J13)<4,"",(AVERAGE(H13,I13)-AVERAGE(G13,J13))/AVERAGE(G13,J13)) | R13: =IF(OR(K13="",COUNT(G13:J13)<4),"",IF(F13="AOI-1",(AVERAGE(H13,I13)-K13)/AVERAGE(H13,I13),(AVERAGE(G13,J13)-K13)/AVERAGE(G13,J13))) | S13: =IF(OR(K13="",P13=""),"",(K13-P13)/K13) | T13: =IF(OR(P13="",#REF!=""),"",(P13-#REF!)/P13) -> #REF!
B14: 8 | C14: 7X4HL05787G7 | D14: 中 | E14: G2 | F14: =IF(E14="G1","AOI-1",IF(E14="G2","AOI-2","")) -> AOI-2 | G14: =IF(C14="","",IFERROR(IF(INDEX(B_選片!$E$4:$E$33,MATCH(C14,B_選片!$C$4:$C$33,0))="","",INDEX(B_選片!$E$4:$E$33,MATCH(C14,B_選片!$C$4:$C$33,0))),"查無")) -> 582 | I14: 11217 | J14: 10353 | K14: 3283 | L14: 3641 | M14: =IF(F14="AOI-1","AOI-2",IF(F14="AOI-2","AOI-1","")) -> AOI-1 | N14: 3000 | O14: AOI-2 | P14: =IF(OR(L14="",COUNT(G14:J14)<4),"",IF(F14="AOI-1",L14*AVERAGE(H14,I14)/AVERAGE(G14,J14),L14*AVERAGE(G14,J14)/AVERAGE(H14,I14))) | Q14: =IF(COUNT(G14:J14)<4,"",(AVERAGE(H14,I14)-AVERAGE(G14,J14))/AVERAGE(G14,J14)) | R14: =IF(OR(K14="",COUNT(G14:J14)<4),"",IF(F14="AOI-1",(AVERAGE(H14,I14)-K14)/AVERAGE(H14,I14),(AVERAGE(G14,J14)-K14)/AVERAGE(G14,J14))) | S14: =IF(OR(K14="",P14=""),"",(K14-P14)/K14) | T14: =IF(OR(P14="",#REF!=""),"",(P14-#REF!)/P14) -> #REF!
B16: 9 | C16: NKAAEEFA77B1 | D16: 高 | E16: G1 | F16: =IF(E16="G1","AOI-1",IF(E16="G2","AOI-2","")) -> AOI-1 | G16: =IF(C16="","",IFERROR(IF(INDEX(B_選片!$E$4:$E$33,MATCH(C16,B_選片!$C$4:$C$33,0))="","",INDEX(B_選片!$E$4:$E$33,MATCH(C16,B_選片!$C$4:$C$33,0))),"查無")) -> 887 | I16: 2131 | J16: 1956 | K16: 966 | L16: 811 | M16: =IF(F16="AOI-1","AOI-2",IF(F16="AOI-2","AOI-1","")) -> AOI-2 | N16: 956 | O16: AOI-1 | P16: =IF(OR(L16="",COUNT(G16:J16)<4),"",IF(F16="AOI-1",L16*AVERAGE(H16,I16)/AVERAGE(G16,J16),L16*AVERAGE(G16,J16)/AVERAGE(H16,I16))) | Q16: =IF(COUNT(G16:J16)<4,"",(AVERAGE(H16,I16)-AVERAGE(G16,J16))/AVERAGE(G16,J16)) | R16: =IF(OR(K16="",COUNT(G16:J16)<4),"",IF(F16="AOI-1",(AVERAGE(H16,I16)-K16)/AVERAGE(H16,I16),(AVERAGE(G16,J16)-K16)/AVERAGE(G16,J16))) | S16: =IF(OR(K16="",P16=""),"",(K16-P16)/K16) | T16: =IF(OR(P16="",#REF!=""),"",(P16-#REF!)/P16) -> #REF!
B17: 10 | C17: NKAAE3342CE2 | D17: 高 | E17: G2 | F17: =IF(E17="G1","AOI-1",IF(E17="G2","AOI-2","")) -> AOI-2 | G17: =IF(C17="","",IFERROR(IF(INDEX(B_選片!$E$4:$E$33,MATCH(C17,B_選片!$C$4:$C$33,0))="","",INDEX(B_選片!$E$4:$E$33,MATCH(C17,B_選片!$C$4:$C$33,0))),"查無")) -> 930 | I17: 3854 | J17: 3645 | K17: 1206 | L17: 1279 | M17: =IF(F17="AOI-1","AOI-2",IF(F17="AOI-2","AOI-1","")) -> AOI-1 | N17: 1120 | O17: AOI-2 | P17: =IF(OR(L17="",COUNT(G17:J17)<4),"",IF(F17="AOI-1",L17*AVERAGE(H17,I17)/AVERAGE(G17,J17),L17*AVERAGE(G17,J17)/AVERAGE(H17,I17))) | Q17: =IF(COUNT(G17:J17)<4,"",(AVERAGE(H17,I17)-AVERAGE(G17,J17))/AVERAGE(G17,J17)) | R17: =IF(OR(K17="",COUNT(G17:J17)<4),"",IF(F17="AOI-1",(AVERAGE(H17,I17)-K17)/AVERAGE(H17,I17),(AVERAGE(G17,J17)-K17)/AVERAGE(G17,J17))) | S17: =IF(OR(K17="",P17=""),"",(K17-P17)/K17) | T17: =IF(OR(P17="",#REF!=""),"",(P17-#REF!)/P17) -> #REF!
B19: 11 | C19: NKAAEE96DAB5 | D19: 高 | E19: G1 | F19: =IF(E19="G1","AOI-1",IF(E19="G2","AOI-2","")) -> AOI-1 | G19: =IF(C19="","",IFERROR(IF(INDEX(B_選片!$E$4:$E$33,MATCH(C19,B_選片!$C$4:$C$33,0))="","",INDEX(B_選片!$E$4:$E$33,MATCH(C19,B_選片!$C$4:$C$33,0))),"查無")) -> 1035 | I19: 6201 | J19: 5552 | K19: 2108 | L19: 1758 | M19: =IF(F19="AOI-1","AOI-2",IF(F19="AOI-2","AOI-1","")) -> AOI-2 | N19: 2072 | O19: AOI-1 | P19: =IF(OR(L19="",COUNT(G19:J19)<4),"",IF(F19="AOI-1",L19*AVERAGE(H19,I19)/AVERAGE(G19,J19),L19*AVERAGE(G19,J19)/AVERAGE(H19,I19))) | Q19: =IF(COUNT(G19:J19)<4,"",(AVERAGE(H19,I19)-AVERAGE(G19,J19))/AVERAGE(G19,J19)) | R19: =IF(OR(K19="",COUNT(G19:J19)<4),"",IF(F19="AOI-1",(AVERAGE(H19,I19)-K19)/AVERAGE(H19,I19),(AVERAGE(G19,J19)-K19)/AVERAGE(G19,J19))) | S19: =IF(OR(K19="",P19=""),"",(K19-P19)/K19) | T19: =IF(OR(P19="",#REF!=""),"",(P19-#REF!)/P19) -> #REF!
B20: 12 | C20: NKAAEB57F7B4 | D20: 高 | E20: G2 | F20: =IF(E20="G1","AOI-1",IF(E20="G2","AOI-2","")) -> AOI-2 | G20: =IF(C20="","",IFERROR(IF(INDEX(B_選片!$E$4:$E$33,MATCH(C20,B_選片!$C$4:$C$33,0))="","",INDEX(B_選片!$E$4:$E$33,MATCH(C20,B_選片!$C$4:$C$33,0))),"查無")) -> 1022 | I20: 3271 | J20: 3066 | K20: 1300 | L20: 1441 | M20: =IF(F20="AOI-1","AOI-2",IF(F20="AOI-2","AOI-1","")) -> AOI-1 | N20: 1222 | O20: AOI-2 | P20: =IF(OR(L20="",COUNT(G20:J20)<4),"",IF(F20="AOI-1",L20*AVERAGE(H20,I20)/AVERAGE(G20,J20),L20*AVERAGE(G20,J20)/AVERAGE(H20,I20))) | Q20: =IF(COUNT(G20:J20)<4,"",(AVERAGE(H20,I20)-AVERAGE(G20,J20))/AVERAGE(G20,J20)) | R20: =IF(OR(K20="",COUNT(G20:J20)<4),"",IF(F20="AOI-1",(AVERAGE(H20,I20)-K20)/AVERAGE(H20,I20),(AVERAGE(G20,J20)-K20)/AVERAGE(G20,J20))) | S20: =IF(OR(K20="",P20=""),"",(K20-P20)/K20) | T20: =IF(OR(P20="",#REF!=""),"",(P20-#REF!)/P20) -> #REF!
B21: 彙總（自動計算）
B22: B1 偵測差（12片平均） | H22: =IFERROR(AVERAGE(Q4:Q20),"待量測") -> 待量測
B23: B2 首道去除率 — AOI-1 先吹（G1） | H23: =IFERROR(AVERAGEIFS(R4:R20,F4:F20,"AOI-1"),"待量測") -> 待量測
B24: B2 首道去除率 — AOI-2 先吹（G2） | H24: =IFERROR(AVERAGEIFS(R4:R20,F4:F20,"AOI-2"),"待量測") -> 待量測
B25: B3 殘留去除率 — AOI-2 後吹（G1） | H25: =IFERROR(AVERAGEIFS(S4:S20,F4:F20,"AOI-1"),"待量測") -> 待量測
B26: B3 殘留去除率 — AOI-1 後吹（G2） | H26: =IFERROR(AVERAGEIFS(S4:S20,F4:F20,"AOI-2"),"待量測") -> 待量測
B27: 回吹去除率 — AOI-1 回吹（G1） | H27: =IFERROR(AVERAGEIFS(T4:T20,F4:F20,"AOI-1"),"待量測") -> 待量測
B28: 回吹去除率 — AOI-2 回吹（G2） | H28: =IFERROR(AVERAGEIFS(T4:T20,F4:F20,"AOI-2"),"待量測") -> 待量測
B29: 換閥前參考（實驗5，2片，舊做法每台連吹 3 趟，與本做法不可直接比較）：首道去除率 AOI-1 約 26%（771A7）、AOI-2 約 41%（880F0）；殘留去除率 AOI-2 後吹 10.2%、AOI-1 後吹 1.1%。第2趟在另一台量測，已依該片 DUC 關時兩台讀值比換算成先吹機台尺度（第2趟校正值）再計算交叉殘留、回吹去除率。

Sheet D_判定總表
A1: 換閥後 DUC 比對 — 判定總表（自動帶入）
B2: 代號 | C2: 指標 | D2: 換閥後結果 | E2: 合格基準 | F2: 判定
B3: B1 | C3: DUC 關偵測差 | D3: =C_清潔力紀錄!H22 -> 待量測 | E3: |差| ≤ 5% | F3: =IF(ISNUMBER(D3),IF(ABS(D3)<=0.05,"合格","不合格"),"待量測") -> 待量測
B4: B3 | C4: 殘留去除率 — AOI-2 後吹 | D4: =C_清潔力紀錄!H25 -> 待量測 | E4: ≤ 5% | F4: =IF(ISNUMBER(D4),IF(ABS(D4)<=0.05,"合格","不合格"),"待量測") -> 待量測
B5: B3 | C5: 殘留去除率 — AOI-1 後吹 | D5: =C_清潔力紀錄!H26 -> 待量測 | E5: ≤ 5% | F5: =IF(ISNUMBER(D5),IF(ABS(D5)<=0.05,"合格","不合格"),"待量測") -> 待量測
B6: B2 | C6: 首道去除率差（AOI-1 − AOI-2） | D6: =IF(AND(ISNUMBER(C_清潔力紀錄!H23),ISNUMBER(C_清潔力紀錄!H24)),C_清潔力紀錄!H23-C_清潔力紀錄!H24,"待量測") -> 待量測 | E6: ≤ 5 個百分點 | F6: =IF(ISNUMBER(D6),IF(ABS(D6)<=0.05,"合格","不合格"),"待量測") -> 待量測
B8: =IF(COUNTIF(F3:F6,"不合格")>0,"◤ 綜合：有項目不合格，請廠商再調整後重測",IF(COUNTIF(F3:F6,"待量測")>0,"◤ 綜合：尚有項目待量測","◤ 綜合：全部合格，建議第22項改判合格")) -> ◤ 綜合：尚有項目待量測
